Workbook

Sheet PREMISSAS
B2: 1. PREMISSAS (PAINEL DE CONTROLE)
F5: QUANTIDADE VENDIDA POR TRIMESTRE
F6: Ano1 | J6: Ano2 | N6: Ano3
B7: PROJEÇÃO DE VENDAS | E7: PREVISÃO | F7: Q1 | G7: Q2 | H7: Q3 | I7: Q4 | J7: Q1 | K7: Q2 | L7: Q3 | M7: Q4 | N7: Q1 | O7: Q2 | P7: Q3 | Q7: Q4
B8: Plano Free (conversões) | F8: 150 | G8: 250 | H8: 380 | I8: 550 | J8: 750 | K8: 1000 | L8: 1300 | M8: 1650 | N8: 2050 | O8: 2500 | P8: 3000 | Q8: 3600
B9: Plano Pro Mensal | F9: 60 | G9: 100 | H9: 155 | I9: 220 | J9: 300 | K9: 400 | L9: 520 | M9: 660 | N9: 820 | O9: 1000 | P9: 1200 | Q9: 1450
B10: Plano Pro Anual | F10: 20 | G10: 35 | H10: 55 | I10: 80 | J10: 110 | K10: 150 | L10: 195 | M10: 250 | N10: 310 | O10: 380 | P10: 460 | Q10: 550
B11: Parcerias / B2B | F11: 0 | G11: 0 | H11: 3 | I11: 7 | J11: 12 | K11: 18 | L11: 26 | M11: 35 | N11: 46 | O11: 58 | P11: 72 | Q11: 88
F12: 0 | G12: 0 | H12: 0 | I12: 0 | J12: 0 | K12: 0 | L12: 0 | M12: 0 | N12: 0 | O12: 0 | P12: 0 | Q12: 0
F13: 0 | G13: 0 | H13: 0 | I13: 0 | J13: 0 | K13: 0 | L13: 0 | M13: 0 | N13: 0 | O13: 0 | P13: 0 | Q13: 0
B15: 1. PREÇO FINAL DOS PRODUTOS ou SERVIÇOS | F15: Reajuste Anual | I15: 3. DESPESAS de SERVIÇOS | N15: Aumento Anual | Q15: 5. INVESTIMENTO INICIAL
F16: 0.1 | N16: 0.1
B17: =B8 -> Plano Free (conversões) | D17: 1 | I17: Mensais | Q17: Lifetime
I18: Agência de Comunicação | L18: 800 | Q18: Investimento Inicial - Reformas | T18: 0
B19: =B9 -> Plano Pro Mensal | D19: 29.9 | I19: Jurídico | L19: 500 | Q19: Investimento Inicial - Máquinas / Equip. | T19: 3000
I20: Contabilidade | L20: 600 | Q20: Investimento Inicial - Mobília | T20: 500
B21: =B10 -> Plano Pro Anual | D21: 199 | I21: Conservação e Limpeza | L21: 0 | Q21: Investimento Inicial - Outros | T21: 5000
I22: Outros (8% contigência) | L22: =SUM(L18:M21)*0.08 -> 152
B23: =B11 -> Parcerias / B2B | D23: 500 | Q23: 6. INVESTIMENTOS RECORRENTES | V23: Aumento Anual
I24: 4. DESPESAS de INFRAESTRUTURA | N24: Aumento Anual | V24: 0.2
B25: =B12 -> 0 | D25: 0 | N25: 0.1 | Q25: Mensais
I26: Mensais | Q26: Marketing Online | T26: 600
B27: =B13 -> 0 | D27: 0 | I27: Aluguel + IPTU | L27: 0 | Q27: Marketing Offline | T27: 200
I28: Energia | L28: 0 | Q28: Treinamento / Capacitação | T28: 300
I29: Telefone | L29: 150 | Q29: Novos Produtos | T29: 400
B30: 2. CUSTOS VARIÁVEIS (CUSTOS DE PRODUÇÃO) | I30: Internet | L30: 200 | Q30: Outros (8% contigência) | T30: =SUM(T26:U29)*0.08 -> 120
I31: Água | L31: 0
B32: =B8 -> Plano Free (conversões) | D32: 0.5 | I32: Condomínio | L32: 0 | Q32: DESCONTOS
I33: Transporte | L33: 0
B34: =B9 -> Plano Pro Mensal | D34: 2 | I34: Documentação | L34: 100 | Q34: Impostos (SIMPLES) | T34: 0.06
I35: Servidores | L35: 800 | Q35: Distribuição Dividendos | T35: 0.2
B36: =B10 -> Plano Pro Anual | D36: 1.5 | I36: Segurança | L36: 0
I37: Materiais de Escritório | L37: 50
B38: =B11 -> Parcerias / B2B | D38: 5 | I38: Materiais de Limpeza | L38: 0
I39: Cartório e Correios | L39: 50
B40: =B12 -> 0 | D40: 0 | I40: Sistemas de Informação | L40: 300
I41: Outros (8% contigência) | L41: =SUM(L27:M40)*0.08 -> 132
B42: =B13 -> 0 | D42: 0

Sheet RH
B2: 7. CUSTO DE MÃO-DE-OBRA
B4: Cargo | C4: Contratação | D4: Salário Base | E4: Desembolso | F4: Reajuste Anual
B5: CEO / Estratégia | C5: Sócio | D5: 800 | E5: =IF(C5=$B$32,D5*$C$32,IF(C5=$B$33,D5*$C$33,IF(C5=$B$34,D5*$C$34,IF(C5=$B$35,D5*$C$35)))) -> 880 | F5: 0.1
B6: CTO / Arquitetura | C6: Sócio | D6: 800 | E6: =IF(C6=$B$32,D6*$C$32,IF(C6=$B$33,D6*$C$33,IF(C6=$B$34,D6*$C$34,IF(C6=$B$35,D6*$C$35)))) -> 880
B7: Dev Full-Stack | C7: Sócio | D7: 800 | E7: =IF(C7=$B$32,D7*$C$32,IF(C7=$B$33,D7*$C$33,IF(C7=$B$34,D7*$C$34,IF(C7=$B$35,D7*$C$35)))) -> 880
B8: Designer UX/UI | C8: Sócio | D8: 800 | E8: =IF(C8=$B$32,D8*$C$32,IF(C8=$B$33,D8*$C$33,IF(C8=$B$34,D8*$C$34,IF(C8=$B$35,D8*$C$35)))) -> 880
B9: Marketing & Growth | C9: Sócio | D9: 800 | E9: =IF(C9=$B$32,D9*$C$32,IF(C9=$B$33,D9*$C$33,IF(C9=$B$34,D9*$C$34,IF(C9=$B$35,D9*$C$35)))) -> 880
B10: Produto & Operações | C10: Sócio | D10: 800 | E10: =IF(C10=$B$32,D10*$C$32,IF(C10=$B$33,D10*$C$33,IF(C10=$B$34,D10*$C$34,IF(C10=$B$35,D10*$C$35)))) -> 880
E11: =IF(C11=$B$32,D11*$C$32,IF(C11=$B$33,D11*$C$33,IF(C11=$B$34,D11*$C$34,IF(C11=$B$35,D11*$C$35)))) -> FALSE
D12: 0 | E12: =IF(C12=$B$32,D12*$C$32,IF(C12=$B$33,D12*$C$33,IF(C12=$B$34,D12*$C$34,IF(C12=$B$35,D12*$C$35)))) -> FALSE
D13: 0 | E13: =IF(C13=$B$32,D13*$C$32,IF(C13=$B$33,D13*$C$33,IF(C13=$B$34,D13*$C$34,IF(C13=$B$35,D13*$C$35)))) -> FALSE
D14: 0 | E14: =IF(C14=$B$32,D14*$C$32,IF(C14=$B$33,D14*$C$33,IF(C14=$B$34,D14*$C$34,IF(C14=$B$35,D14*$C$35)))) -> FALSE
D17: Ano1 | H17: Ano2 | L17: Ano3
B18: Cargo | C18: Contratação | D18: Q1 | E18: Q2 | F18: Q3 | G18: Q4 | H18: Q1 | I18: Q2 | J18: Q3 | K18: Q4 | L18: Q1 | M18: Q2 | N18: Q3 | O18: Q4
B19: =B5 -> CEO / Estratégia | C19: =C5 -> Sócio | D19: 1 | E19: 1 | F19: 1 | G19: 1 | H19: 1 | I19: 1 | J19: 1 | K19: 1 | L19: 1 | M19: 1 | N19: 1 | O19: 1
B20: =B6 -> CTO / Arquitetura | C20: =C6 -> Sócio | D20: 1 | E20: 1 | F20: 1 | G20: 1 | H20: 1 | I20: 1 | J20: 1 | K20: 1 | L20: 1 | M20: 1 | N20: 1 | O20: 1
B21: =B7 -> Dev Full-Stack | C21: =C7 -> Sócio | D21: 1 | E21: 1 | F21: 1 | G21: 1 | H21: 1 | I21: 1 | J21: 1 | K21: 1 | L21: 1 | M21: 1 | N21: 1 | O21: 1
B22: =B8 -> Designer UX/UI | C22: =C8 -> Sócio | D22: 0 | E22: 0 | F22: 0 | G22: 0 | H22: 1 | I22: 1 | J22: 1 | K22: 1 | L22: 1 | M22: 1 | N22: 1 | O22: 1
B23: =B9 -> Marketing & Growth | C23: =C9 -> Sócio | D23: 0 | E23: 0 | F23: 0 | G23: 0 | H23: 1 | I23: 1 | J23: 1 | K23: 1 | L23: 1 | M23: 1 | N23: 1 | O23: 1
B24: =B10 -> Produto & Operações | C24: =C10 -> Sócio | D24: 0 | E24: 0 | F24: 0 | G24: 0 | H24: 1 | I24: 1 | J24: 1 | K24: 1 | L24: 1 | M24: 1 | N24: 1 | O24: 1
B25: =B11 -> 0 | C25: =C11 -> 0 | D25: 0 | E25: 0 | F25: 0 | G25: 0 | H25: 0 | I25: 0 | J25: 0 | K25: 0 | L25: 0 | M25: 0 | N25: 0 | O25: 0
B26: =B12 -> 0 | C26: =C12 -> 0 | D26: 0 | E26: 0 | F26: 0 | G26: 0 | H26: 0 | I26: 0 | J26: 0 | K26: 0 | L26: 0 | M26: 0 | N26: 0 | O26: 0
B27: =B13 -> 0 | C27: =C13 -> 0 | D27: 0 | E27: 0 | F27: 0 | G27: 0 | H27: 0 | I27: 0 | J27: 0 | K27: 0 | L27: 0 | M27: 0 | N27: 0 | O27: 0
B28: =B14 -> 0 | C28: =C14 -> 0 | D28: 0 | E28: 0 | F28: 0 | G28: 0 | H28: 0 | I28: 0 | J28: 0 | K28: 0 | L28: 0 | M28: 0 | N28: 0 | O28: 0
C29: Total | D29: =SUM(D19:D28) -> 3 | E29: =SUM(E19:E28) -> 3 | F29: =SUM(F19:F28) -> 3 | G29: =SUM(G19:G28) -> 3 | H29: =SUM(H19:H28) -> 6 | I29: =SUM(I19:I28) -> 6 | J29: =SUM(J19:J28) -> 6 | K29: =SUM(K19:K28) -> 6 | ... O29: =SUM(O19:O28) -> 6
B31: ENCARGOS
B32: CLT | C32: 1.4
B33: Sócio | C33: 1.1
B34: Estágio | C34: 1
B35: PJ | C35: 1

Sheet RESULTADO (DRE)
B2: 3. DETALHAMENTO FINANCEIRO
F4: 1st Year | J4: 2nd Year | N4: 3rd Year
E5: Tempo 0 | F5: Q1 | G5: Q2 | H5: Q3 | I5: Q4 | J5: Q1 | K5: Q2 | L5: Q3 | M5: Q4 | N5: Q1 | O5: Q2 | P5: Q3 | Q5: Q4 | S5: 1st Year | T5: 2nd Year | U5: 3rd Year
B6: 1. Receita Bruta por Produto | F6: =SUM(F7:F12) -> 5924 | G6: =SUM(G7:G12) -> 10205 | H6: =SUM(H7:H12) -> 17459.5 | I6: =SUM(I7:I12) -> 26548 | J6: =SUM(J7:J12) -> 41371 | K6: =SUM(K7:K12) -> 51810 | L6: =SUM(L7:L12) -> 68653 | M6: =SUM(M7:M12) -> 88634 | ... Q6: =SUM(Q7:Q12) -> 200405 | S6: =SUM(F6:I6) -> 60136.5 | T6: =SUM(J6:M6) -> 250468 | U6: =SUM(N6:Q6) -> 626228.8
B7: =PREMISSAS!B8 -> Plano Free (conversões) | F7: =PREMISSAS!F8*PREMISSAS!$D$17 -> 150 | G7: =PREMISSAS!G8*PREMISSAS!$D$17 -> 250 | H7: =PREMISSAS!H8*PREMISSAS!$D$17 -> 380 | I7: =PREMISSAS!I8*PREMISSAS!$D$17 -> 550 | J7: =(PREMISSAS!J8*PREMISSAS!$D$17*PREMISSAS!$F$16)+PREMISSAS!J8*PREMISSAS!$D$17 -> 825 | K7: =PREMISSAS!K8*PREMISSAS!$D$17 -> 1000 | L7: =PREMISSAS!L8*PREMISSAS!$D$17 -> 1300 | M7: =PREMISSAS!M8*PREMISSAS!$D$17 -> 1650 | N7: =(PREMISSAS!N8*PREMISSAS!$D$17*PREMISSAS!$F$16)+PREMISSAS!N8*PREMISSAS!$D$17 -> 2255 | O7: =PREMISSAS!O8*PREMISSAS!$D$17 -> 2500 | P7: =PREMISSAS!P8*PREMISSAS!$D$17 -> 3000 | Q7: =PREMISSAS!Q8*PREMISSAS!$D$17 -> 3600 | S7: =SUM(F7:I7) -> 1330 | T7: =SUM(J7:M7) -> 4775 | U7: =SUM(N7:Q7) -> 11355
B8: =PREMISSAS!B9 -> Plano Pro Mensal | F8: =PREMISSAS!F9*PREMISSAS!$D$19 -> 1794 | G8: =PREMISSAS!G9*PREMISSAS!$D$19 -> 2990 | H8: =PREMISSAS!H9*PREMISSAS!$D$19 -> 4634.5 | I8: =PREMISSAS!I9*PREMISSAS!$D$19 -> 6578 | J8: =(PREMISSAS!J9*PREMISSAS!$D$19*PREMISSAS!$F$16)+PREMISSAS!J9*PREMISSAS!$D$19 -> 9867 | K8: =PREMISSAS!K9*PREMISSAS!$D$19 -> 11960 | L8: =PREMISSAS!L9*PREMISSAS!$D$19 -> 15548 | M8: =PREMISSAS!M9*PREMISSAS!$D$19 -> 19734 | N8: =(PREMISSAS!N9*PREMISSAS!$D$19*PREMISSAS!$F$16)+PREMISSAS!N9*PREMISSAS!$D$19 -> 26969.8 | O8: =PREMISSAS!O9*PREMISSAS!$D$19 -> 29900 | P8: =PREMISSAS!P9*PREMISSAS!$D$19 -> 35880 | Q8: =PREMISSAS!Q9*PREMISSAS!$D$19 -> 43355 | S8: =SUM(F8:I8) -> 15996.5 | T8: =SUM(J8:M8) -> 57109 | U8: =SUM(N8:Q8) -> 136104.8
B9: =PREMISSAS!B10 -> Plano Pro Anual | F9: =PREMISSAS!F10*PREMISSAS!$D$21 -> 3980 | G9: =PREMISSAS!G10*PREMISSAS!$D$21 -> 6965 | H9: =PREMISSAS!H10*PREMISSAS!$D$21 -> 10945 | I9: =PREMISSAS!I10*PREMISSAS!$D$21 -> 15920 | J9: =(PREMISSAS!J10*PREMISSAS!$D$21*PREMISSAS!$F$16)+PREMISSAS!J10*PREMISSAS!$D$21 -> 24079 | K9: =PREMISSAS!K10*PREMISSAS!$D$21 -> 29850 | L9: =PREMISSAS!L10*PREMISSAS!$D$21 -> 38805 | M9: =PREMISSAS!M10*PREMISSAS!$D$21 -> 49750 | N9: =(PREMISSAS!N10*PREMISSAS!$D$21*PREMISSAS!$F$16)+PREMISSAS!N10*PREMISSAS!$D$21 -> 67859 | O9: =PREMISSAS!O10*PREMISSAS!$D$21 -> 75620 | P9: =PREMISSAS!P10*PREMISSAS!$D$21 -> 91540 | Q9: =PREMISSAS!Q10*PREMISSAS!$D$21 -> 109450 | S9: =SUM(F9:I9) -> 37810 | T9: =SUM(J9:M9) -> 142484 | U9: =SUM(N9:Q9) -> 344469
B10: =PREMISSAS!B11 -> Parcerias / B2B | F10: =PREMISSAS!F11*PREMISSAS!$D$23 -> 0 | G10: =PREMISSAS!G11*PREMISSAS!$D$23 -> 0 | H10: =PREMISSAS!H11*PREMISSAS!$D$23 -> 1500 | I10: =PREMISSAS!I11*PREMISSAS!$D$23 -> 3500 | J10: =(PREMISSAS!J11*PREMISSAS!$D$23*PREMISSAS!$F$16)+PREMISSAS!J11*PREMISSAS!$D$23 -> 6600 | K10: =PREMISSAS!K11*PREMISSAS!$D$23 -> 9000 | L10: =PREMISSAS!L11*PREMISSAS!$D$23 -> 13000 | M10: =PREMISSAS!M11*PREMISSAS!$D$23 -> 17500 | N10: =(PREMISSAS!N11*PREMISSAS!$D$23*PREMISSAS!$F$16)+PREMISSAS!N11*PREMISSAS!$D$23 -> 25300 | O10: =PREMISSAS!O11*PREMISSAS!$D$23 -> 29000 | P10: =PREMISSAS!P11*PREMISSAS!$D$23 -> 36000 | Q10: =PREMISSAS!Q11*PREMISSAS!$D$23 -> 44000 | S10: =SUM(F10:I10) -> 5000 | T10: =SUM(J10:M10) -> 46100 | U10: =SUM(N10:Q10) -> 134300
B11: =PREMISSAS!B12 -> 0 | F11: =PREMISSAS!F12*PREMISSAS!$D$25 -> 0 | G11: =PREMISSAS!G12*PREMISSAS!$D$25 -> 0 | H11: =PREMISSAS!H12*PREMISSAS!$D$25 -> 0 | I11: =PREMISSAS!I12*PREMISSAS!$D$25 -> 0 | J11: =(PREMISSAS!J12*PREMISSAS!$D$25*PREMISSAS!$F$16)+PREMISSAS!J12*PREMISSAS!$D$25 -> 0 | K11: =PREMISSAS!K12*PREMISSAS!$D$25 -> 0 | L11: =PREMISSAS!L12*PREMISSAS!$D$25 -> 0 | M11: =PREMISSAS!M12*PREMISSAS!$D$25 -> 0 | N11: =(PREMISSAS!N12*PREMISSAS!$D$25*PREMISSAS!$F$16)+PREMISSAS!N12*PREMISSAS!$D$25 -> 0 | O11: =PREMISSAS!O12*PREMISSAS!$D$25 -> 0 | P11: =PREMISSAS!P12*PREMISSAS!$D$25 -> 0 | Q11: =PREMISSAS!Q12*PREMISSAS!$D$25 -> 0 | S11: =SUM(F11:I11) -> 0 | T11: =SUM(J11:M11) -> 0 | U11: =SUM(N11:Q11) -> 0
B12: =PREMISSAS!B13 -> 0 | F12: =PREMISSAS!F13*PREMISSAS!$D$27 -> 0 | G12: =PREMISSAS!G13*PREMISSAS!$D$27 -> 0 | H12: =PREMISSAS!H13*PREMISSAS!$D$27 -> 0 | I12: =PREMISSAS!I13*PREMISSAS!$D$27 -> 0 | J12: =(PREMISSAS!J13*PREMISSAS!$D$27*PREMISSAS!$F$16)+PREMISSAS!J13*PREMISSAS!$D$27 -> 0 | K12: =PREMISSAS!K13*PREMISSAS!$D$27 -> 0 | L12: =PREMISSAS!L13*PREMISSAS!$D$27 -> 0 | M12: =PREMISSAS!M13*PREMISSAS!$D$27 -> 0 | N12: =(PREMISSAS!N13*PREMISSAS!$D$27*PREMISSAS!$F$16)+PREMISSAS!N13*PREMISSAS!$D$27 -> 0 | O12: =PREMISSAS!O13*PREMISSAS!$D$27 -> 0 | P12: =PREMISSAS!P13*PREMISSAS!$D$27 -> 0 | Q12: =PREMISSAS!Q13*PREMISSAS!$D$27 -> 0 | S12: =SUM(F12:I12) -> 0 | T12: =SUM(J12:M12) -> 0 | U12: =SUM(N12:Q12) -> 0
B14: 2. Custos Variáveis por Produto | F14: =SUM(F15:F20) -> 225 | G14: =SUM(G15:G20) -> 377.5 | H14: =SUM(H15:H20) -> 597.5 | I14: =SUM(I15:I20) -> 870 | J14: =SUM(J15:J20) -> 1200 | K14: =SUM(K15:K20) -> 1615 | L14: =SUM(L15:L20) -> 2112.5 | M14: =SUM(M15:M20) -> 2695 | ... Q14: =SUM(Q15:Q20) -> 5965 | S14: =SUM(F14:I14) -> 2070 | T14: =SUM(J14:M14) -> 7622.5 | U14: =SUM(N14:Q14) -> 18385
B15: =PREMISSAS!B32 -> Plano Free (conversões) | F15: =PREMISSAS!F8*PREMISSAS!$D$32 -> 75 | G15: =PREMISSAS!G8*PREMISSAS!$D$32 -> 125 | H15: =PREMISSAS!H8*PREMISSAS!$D$32 -> 190 | I15: =PREMISSAS!I8*PREMISSAS!$D$32 -> 275 | J15: =PREMISSAS!J8*PREMISSAS!$D$32 -> 375 | K15: =PREMISSAS!K8*PREMISSAS!$D$32 -> 500 | L15: =PREMISSAS!L8*PREMISSAS!$D$32 -> 650 | M15: =PREMISSAS!M8*PREMISSAS!$D$32 -> 825 | ... Q15: =PREMISSAS!Q8*PREMISSAS!$D$32 -> 1800 | S15: =SUM(F15:I15) -> 665 | T15: =SUM(J15:M15) -> 2350 | U15: =SUM(N15:Q15) -> 5575
B16: =PREMISSAS!B34 -> Plano Pro Mensal | F16: =PREMISSAS!F9*PREMISSAS!$D$34 -> 120 | G16: =PREMISSAS!G9*PREMISSAS!$D$34 -> 200 | H16: =PREMISSAS!H9*PREMISSAS!$D$34 -> 310 | I16: =PREMISSAS!I9*PREMISSAS!$D$34 -> 440 | J16: =PREMISSAS!J9*PREMISSAS!$D$34 -> 600 | K16: =PREMISSAS!K9*PREMISSAS!$D$34 -> 800 | L16: =PREMISSAS!L9*PREMISSAS!$D$34 -> 1040 | M16: =PREMISSAS!M9*PREMISSAS!$D$34 -> 1320 | ... Q16: =PREMISSAS!Q9*PREMISSAS!$D$34 -> 2900 | S16: =SUM(F16:I16) -> 1070 | T16: =SUM(J16:M16) -> 3760 | U16: =SUM(N16:Q16) -> 8940
B17: =PREMISSAS!B36 -> Plano Pro Anual | F17: =PREMISSAS!F10*PREMISSAS!$D$36 -> 30 | G17: =PREMISSAS!G10*PREMISSAS!$D$36 -> 52.5 | H17: =PREMISSAS!H10*PREMISSAS!$D$36 -> 82.5 | I17: =PREMISSAS!I10*PREMISSAS!$D$36 -> 120 | J17: =PREMISSAS!J10*PREMISSAS!$D$36 -> 165 | K17: =PREMISSAS!K10*PREMISSAS!$D$36 -> 225 | L17: =PREMISSAS!L10*PREMISSAS!$D$36 -> 292.5 | M17: =PREMISSAS!M10*PREMISSAS!$D$36 -> 375 | ... Q17: =PREMISSAS!Q10*PREMISSAS!$D$36 -> 825 | S17: =SUM(F17:I17) -> 285 | T17: =SUM(J17:M17) -> 1057.5 | U17: =SUM(N17:Q17) -> 2550
B18: =PREMISSAS!B38 -> Parcerias / B2B | F18: =PREMISSAS!F11*PREMISSAS!$D$38 -> 0 | G18: =PREMISSAS!G11*PREMISSAS!$D$38 -> 0 | H18: =PREMISSAS!H11*PREMISSAS!$D$38 -> 15 | I18: =PREMISSAS!I11*PREMISSAS!$D$38 -> 35 | J18: =PREMISSAS!J11*PREMISSAS!$D$38 -> 60 | K18: =PREMISSAS!K11*PREMISSAS!$D$38 -> 90 | L18: =PREMISSAS!L11*PREMISSAS!$D$38 -> 130 | M18: =PREMISSAS!M11*PREMISSAS!$D$38 -> 175 | ... Q18: =PREMISSAS!Q11*PREMISSAS!$D$38 -> 440 | S18: =SUM(F18:I18) -> 50 | T18: =SUM(J18:M18) -> 455 | U18: =SUM(N18:Q18) -> 1320
B19: =PREMISSAS!B40 -> 0 | F19: =PREMISSAS!F12*PREMISSAS!$D$40 -> 0 | G19: =PREMISSAS!G12*PREMISSAS!$D$40 -> 0 | H19: =PREMISSAS!H12*PREMISSAS!$D$40 -> 0 | I19: =PREMISSAS!I12*PREMISSAS!$D$40 -> 0 | J19: =PREMISSAS!J12*PREMISSAS!$D$40 -> 0 | K19: =PREMISSAS!K12*PREMISSAS!$D$40 -> 0 | L19: =PREMISSAS!L12*PREMISSAS!$D$40 -> 0 | M19: =PREMISSAS!M12*PREMISSAS!$D$40 -> 0 | ... Q19: =PREMISSAS!Q12*PREMISSAS!$D$40 -> 0 | S19: =SUM(F19:I19) -> 0 | T19: =SUM(J19:M19) -> 0 | U19: =SUM(N19:Q19) -> 0
B20: =PREMISSAS!B42 -> 0 | F20: =PREMISSAS!F13*PREMISSAS!$D$42 -> 0 | G20: =PREMISSAS!G13*PREMISSAS!$D$42 -> 0 | H20: =PREMISSAS!H13*PREMISSAS!$D$42 -> 0 | I20: =PREMISSAS!I13*PREMISSAS!$D$42 -> 0 | J20: =PREMISSAS!J13*PREMISSAS!$D$42 -> 0 | K20: =PREMISSAS!K13*PREMISSAS!$D$42 -> 0 | L20: =PREMISSAS!L13*PREMISSAS!$D$42 -> 0 | M20: =PREMISSAS!M13*PREMISSAS!$D$42 -> 0 | ... Q20: =PREMISSAS!Q13*PREMISSAS!$D$42 -> 0 | S20: =SUM(F20:I20) -> 0 | T20: =SUM(J20:M20) -> 0 | U20: =SUM(N20:Q20) -> 0
B22: Resultado Operacional | F22: =F6-F14 -> 5699 | G22: =G6-G14 -> 9827.5 | H22: =H6-H14 -> 16862 | I22: =I6-I14 -> 25678 | J22: =J6-J14 -> 40171 | K22: =K6-K14 -> 50195 | L22: =L6-L14 -> 66540.5 | M22: =M6-M14 -> 85939 | ... Q22: =Q6-Q14 -> 194440 | S22: =SUM(F22:I22) -> 58066.5 | T22: =SUM(J22:M22) -> 242845.5 | U22: =SUM(N22:Q22) -> 607843.8
B23: Margem Operacional | F23: =F22/F6 -> 0.96201891 | G23: =G22/G6 -> 0.96300833 | H23: =H22/H6 -> 0.96577794 | I23: =I22/I6 -> 0.96722917 | J23: =J22/J6 -> 0.97099417 | K23: =K22/K6 -> 0.96882841 | L23: =L22/L6 -> 0.96922931 | M23: =M22/M6 -> 0.96959406 | ... Q23: =Q22/Q6 -> 0.97023527 | S23: =AVERAGE(F23:I23) -> 0.96450859 | T23: =AVERAGE(J23:M23) -> 0.96966149 | U23: =AVERAGE(N23:Q23) -> 0.97076025
B25: 3. Despesas de Serviços | F25: =SUM(F26:F30) -> 6156 | G25: =SUM(G26:G30) -> 6156 | H25: =SUM(H26:H30) -> 6156 | I25: =SUM(I26:I30) -> 6156 | J25: =SUM(J26:J30) -> 6771.6 | K25: =SUM(K26:K30) -> 6771.6 | L25: =SUM(L26:L30) -> 6771.6 | M25: =SUM(M26:M30) -> 6771.6 | ... Q25: =SUM(Q26:Q30) -> 7448.76 | S25: =SUM(F25:I25) -> 24624 | T25: =SUM(J25:M25) -> 27086.4 | U25: =SUM(N25:Q25) -> 29795.04
B26: =PREMISSAS!I18 -> Agência de Comunicação | F26: =PREMISSAS!L18*3 -> 2400 | G26: =F26 -> 2400 | H26: =G26 -> 2400 | I26: =H26 -> 2400 | J26: =I26+(I26*PREMISSAS!$N$16) -> 2640 | K26: =J26 -> 2640 | L26: =K26 -> 2640 | M26: =L26 -> 2640 | N26: =M26+(M26*PREMISSAS!$N$16) -> 2904 | O26: =N26 -> 2904 | P26: =O26 -> 2904 | Q26: =P26 -> 2904 | S26: =SUM(F26:I26) -> 9600 | T26: =SUM(J26:M26) -> 10560 | U26: =SUM(N26:Q26) -> 11616
B27: =PREMISSAS!I19 -> Jurídico | F27: =PREMISSAS!L19*3 -> 1500 | G27: =F27 -> 1500 | H27: =G27 -> 1500 | I27: =H27 -> 1500 | J27: =I27+(I27*PREMISSAS!$N$16) -> 1650 | K27: =J27 -> 1650 | L27: =K27 -> 1650 | M27: =L27 -> 1650 | N27: =M27+(M27*PREMISSAS!$N$16) -> 1815 | O27: =N27 -> 1815 | P27: =O27 -> 1815 | Q27: =P27 -> 1815 | S27: =SUM(F27:I27) -> 6000 | T27: =SUM(J27:M27) -> 6600 | U27: =SUM(N27:Q27) -> 7260
B28: =PREMISSAS!I20 -> Contabilidade | F28: =PREMISSAS!L20*3 -> 1800 | G28: =F28 -> 1800 | H28: =G28 -> 1800 | I28: =H28 -> 1800 | J28: =I28+(I28*PREMISSAS!$N$16) -> 1980 | K28: =J28 -> 1980 | L28: =K28 -> 1980 | M28: =L28 -> 1980 | N28: =M28+(M28*PREMISSAS!$N$16) -> 2178 | O28: =N28 -> 2178 | P28: =O28 -> 2178 | Q28: =P28 -> 2178 | S28: =SUM(F28:I28) -> 7200 | T28: =SUM(J28:M28) -> 7920 | U28: =SUM(N28:Q28) -> 8712
B29: =PREMISSAS!I21 -> Conservação e Limpeza | F29: =PREMISSAS!L21*3 -> 0 | G29: =F29 -> 0 | H29: =G29 -> 0 | I29: =H29 -> 0 | J29: =I29+(I29*PREMISSAS!$N$16) -> 0 | K29: =J29 -> 0 | L29: =K29 -> 0 | M29: =L29 -> 0 | N29: =M29+(M29*PREMISSAS!$N$16) -> 0 | O29: =N29 -> 0 | P29: =O29 -> 0 | Q29: =P29 -> 0 | S29: =SUM(F29:I29) -> 0 | T29: =SUM(J29:M29) -> 0 | U29: =SUM(N29:Q29) -> 0
B30: =PREMISSAS!I22 -> Outros (8% contigência) | F30: =PREMISSAS!L22*3 -> 456 | G30: =F30 -> 456 | H30: =G30 -> 456 | I30: =H30 -> 456 | J30: =I30+(I30*PREMISSAS!$N$16) -> 501.6 | K30: =J30 -> 501.6 | L30: =K30 -> 501.6 | M30: =L30 -> 501.6 | N30: =M30+(M30*PREMISSAS!$N$16) -> 551.76 | O30: =N30 -> 551.76 | P30: =O30 -> 551.76 | Q30: =P30 -> 551.76 | S30: =SUM(F30:I30) -> 1824 | T30: =SUM(J30:M30) -> 2006.4 | U30: =SUM(N30:Q30) -> 2207.04
B32: 4. Despesas de Infraestrutura | E32: =SUM(E33:E47) -> 0 | F32: =SUM(F33:F47) -> 5346 | G32: =SUM(G33:G47) -> 5346 | H32: =SUM(H33:H47) -> 5346 | I32: =SUM(I33:I47) -> 5346 | J32: =SUM(J33:J47) -> 5880.6 | K32: =SUM(K33:K47) -> 5880.6 | L32: =SUM(L33:L47) -> 5880.6 | ... Q32: =SUM(Q33:Q47) -> 6468.66 | S32: =SUM(F32:I32) -> 21384 | T32: =SUM(J32:M32) -> 23522.4 | U32: =SUM(N32:Q32) -> 25874.64
B33: =PREMISSAS!I27 -> Aluguel + IPTU | F33: =PREMISSAS!L27*3 -> 0 | G33: =F33 -> 0 | H33: =G33 -> 0 | I33: =H33 -> 0 | J33: =I33+(I33*PREMISSAS!$N$25) -> 0 | K33: =J33 -> 0 | L33: =K33 -> 0 | M33: =L33 -> 0 | N33: =M33+(M33*PREMISSAS!$N$25) -> 0 | O33: =N33 -> 0 | P33: =O33 -> 0 | Q33: =P33 -> 0 | S33: =SUM(F33:I33) -> 0 | T33: =SUM(J33:M33) -> 0 | U33: =SUM(N33:Q33) -> 0
B34: =PREMISSAS!I28 -> Energia | F34: =PREMISSAS!L28*3 -> 0 | G34: =F34 -> 0 | H34: =G34 -> 0 | I34: =H34 -> 0 | J34: =I34+(I34*PREMISSAS!$N$25) -> 0 | K34: =J34 -> 0 | L34: =K34 -> 0 | M34: =L34 -> 0 | N34: =M34+(M34*PREMISSAS!$N$25) -> 0 | O34: =N34 -> 0 | P34: =O34 -> 0 | Q34: =P34 -> 0 | S34: =SUM(F34:I34) -> 0 | T34: =SUM(J34:M34) -> 0 | U34: =SUM(N34:Q34) -> 0
B35: =PREMISSAS!I29 -> Telefone | F35: =PREMISSAS!L29*3 -> 450 | G35: =F35 -> 450 | H35: =G35 -> 450 | I35: =H35 -> 450 | J35: =I35+(I35*PREMISSAS!$N$25) -> 495 | K35: =J35 -> 495 | L35: =K35 -> 495 | M35: =L35 -> 495 | N35: =M35+(M35*PREMISSAS!$N$25) -> 544.5 | O35: =N35 -> 544.5 | P35: =O35 -> 544.5 | Q35: =P35 -> 544.5 | S35: =SUM(F35:I35) -> 1800 | T35: =SUM(J35:M35) -> 1980 | U35: =SUM(N35:Q35) -> 2178
B36: =PREMISSAS!I30 -> Internet | F36: =PREMISSAS!L30*3 -> 600 | G36: =F36 -> 600 | H36: =G36 -> 600 | I36: =H36 -> 600 | J36: =I36+(I36*PREMISSAS!$N$25) -> 660 | K36: =J36 -> 660 | L36: =K36 -> 660 | M36: =L36 -> 660 | N36: =M36+(M36*PREMISSAS!$N$25) -> 726 | O36: =N36 -> 726 | P36: =O36 -> 726 | Q36: =P36 -> 726 | S36: =SUM(F36:I36) -> 2400 | T36: =SUM(J36:M36) -> 2640 | U36: =SUM(N36:Q36) -> 2904
B37: =PREMISSAS!I31 -> Água | F37: =PREMISSAS!L31*3 -> 0 | G37: =F37 -> 0 | H37: =G37 -> 0 | I37: =H37 -> 0 | J37: =I37+(I37*PREMISSAS!$N$25) -> 0 | K37: =J37 -> 0 | L37: =K37 -> 0 | M37: =L37 -> 0 | N37: =M37+(M37*PREMISSAS!$N$25) -> 0 | O37: =N37 -> 0 | P37: =O37 -> 0 | Q37: =P37 -> 0 | S37: =SUM(F37:I37) -> 0 | T37: =SUM(J37:M37) -> 0 | U37: =SUM(N37:Q37) -> 0
B38: =PREMISSAS!I32 -> Condomínio | F38: =PREMISSAS!L32*3 -> 0 | G38: =F38 -> 0 | H38: =G38 -> 0 | I38: =H38 -> 0 | J38: =I38+(I38*PREMISSAS!$N$25) -> 0 | K38: =J38 -> 0 | L38: =K38 -> 0 | M38: =L38 -> 0 | N38: =M38+(M38*PREMISSAS!$N$25) -> 0 | O38: =N38 -> 0 | P38: =O38 -> 0 | Q38: =P38 -> 0 | S38: =SUM(F38:I38) -> 0 | T38: =SUM(J38:M38) -> 0 | U38: =SUM(N38:Q38) -> 0
B39: =PREMISSAS!I33 -> Transporte | F39: =PREMISSAS!L33*3 -> 0 | G39: =F39 -> 0 | H39: =G39 -> 0 | I39: =H39 -> 0 | J39: =I39+(I39*PREMISSAS!$N$25) -> 0 | K39: =J39 -> 0 | L39: =K39 -> 0 | M39: =L39 -> 0 | N39: =M39+(M39*PREMISSAS!$N$25) -> 0 | O39: =N39 -> 0 | P39: =O39 -> 0 | Q39: =P39 -> 0 | S39: =SUM(F39:I39) -> 0 | T39: =SUM(J39:M39) -> 0 | U39: =SUM(N39:Q39) -> 0
B40: =PREMISSAS!I34 -> Documentação | F40: =PREMISSAS!L34*3 -> 300 | G40: =F40 -> 300 | H40: =G40 -> 300 | I40: =H40 -> 300 | J40: =I40+(I40*PREMISSAS!$N$25) -> 330 | K40: =J40 -> 330 | L40: =K40 -> 330 | M40: =L40 -> 330 | N40: =M40+(M40*PREMISSAS!$N$25) -> 363 | O40: =N40 -> 363 | P40: =O40 -> 363 | Q40: =P40 -> 363 | S40: =SUM(F40:I40) -> 1200 | T40: =SUM(J40:M40) -> 1320 | U40: =SUM(N40:Q40) -> 1452
B41: =PREMISSAS!I35 -> Servidores | F41: =PREMISSAS!L35*3 -> 2400 | G41: =F41 -> 2400 | H41: =G41 -> 2400 | I41: =H41 -> 2400 | J41: =I41+(I41*PREMISSAS!$N$25) -> 2640 | K41: =J41 -> 2640 | L41: =K41 -> 2640 | M41: =L41 -> 2640 | N41: =M41+(M41*PREMISSAS!$N$25) -> 2904 | O41: =N41 -> 2904 | P41: =O41 -> 2904 | Q41: =P41 -> 2904 | S41: =SUM(F41:I41) -> 9600 | T41: =SUM(J41:M41) -> 10560 | U41: =SUM(N41:Q41) -> 11616
B42: =PREMISSAS!I36 -> Segurança | F42: =PREMISSAS!L36*3 -> 0 | G42: =F42 -> 0 | H42: =G42 -> 0 | I42: =H42 -> 0 | J42: =I42+(I42*PREMISSAS!$N$25) -> 0 | K42: =J42 -> 0 | L42: =K42 -> 0 | M42: =L42 -> 0 | N42: =M42+(M42*PREMISSAS!$N$25) -> 0 | O42: =N42 -> 0 | P42: =O42 -> 0 | Q42: =P42 -> 0 | S42: =SUM(F42:I42) -> 0 | T42: =SUM(J42:M42) -> 0 | U42: =SUM(N42:Q42) -> 0
B43: =PREMISSAS!I37 -> Materiais de Escritório | F43: =PREMISSAS!L37*3 -> 150 | G43: =F43 -> 150 | H43: =G43 -> 150 | I43: =H43 -> 150 | J43: =I43+(I43*PREMISSAS!$N$25) -> 165 | K43: =J43 -> 165 | L43: =K43 -> 165 | M43: =L43 -> 165 | N43: =M43+(M43*PREMISSAS!$N$25) -> 181.5 | O43: =N43 -> 181.5 | P43: =O43 -> 181.5 | Q43: =P43 -> 181.5 | S43: =SUM(F43:I43) -> 600 | T43: =SUM(J43:M43) -> 660 | U43: =SUM(N43:Q43) -> 726
B44: =PREMISSAS!I38 -> Materiais de Limpeza | F44: =PREMISSAS!L38*3 -> 0 | G44: =F44 -> 0 | H44: =G44 -> 0 | I44: =H44 -> 0 | J44: =I44+(I44*PREMISSAS!$N$25) -> 0 | K44: =J44 -> 0 | L44: =K44 -> 0 | M44: =L44 -> 0 | N44: =M44+(M44*PREMISSAS!$N$25) -> 0 | O44: =N44 -> 0 | P44: =O44 -> 0 | Q44: =P44 -> 0 | S44: =SUM(F44:I44) -> 0 | T44: =SUM(J44:M44) -> 0 | U44: =SUM(N44:Q44) -> 0
... B47: =PREMISSAS!I41 -> Outros (8% contigência) | F47: =PREMISSAS!L41*3 -> 396 | G47: =F47 -> 396 | H47: =G47 -> 396 | I47: =H47 -> 396 | J47: =I47+(I47*PREMISSAS!$N$25) -> 435.6 | K47: =J47 -> 435.6 | L47: =K47 -> 435.6 | M47: =L47 -> 435.6 | N47: =M47+(M47*PREMISSAS!$N$25) -> 479.16 | O47: =N47 -> 479.16 | P47: =O47 -> 479.16 | Q47: =P47 -> 479.16 | S47: =SUM(F47:I47) -> 1584 | T47: =SUM(J47:M47) -> 1742.4 | U47: =SUM(N47:Q47) -> 1916.64
B49: 5. Investimento Inicial | E49: =SUM(E50:E53) -> 8500 | S49: =SUM(E49:Q49) -> 8500 | T49: =SUM(J49:M49) -> 0 | U49: =SUM(N49:Q49) -> 0
...

Sheet VIABILIDADE
B2: VIABILIDADE
B4: Fluxo de Caixa Acumulado
B30: Lucratividade | J30: INDICADORES
B31: A lucratividade é o percentual que representa o lucro líquido em relação ao faturamento.
J32: Necessidade de Capital | M32: =MIN('RESULTADO (DRE)'!F82:Q82)*-1 -> 35132.81
C33: Lucratividade (%) = | D33: Resultado Final (média 3 anos) | E33: x 100 = | F33: =(AVERAGE('RESULTADO (DRE)'!F81:Q81)/AVERAGE('RESULTADO (DRE)'!F6:Q6)) -> 0.46979957
D34: Receita Total (média 3 anos) | J34: VPL | M34: =VIABILIDADE!D40 -> 532504.49
B36: Valor presente líquido (3anos) - fluxo de caixa | J36: Margem Operacional | M36: =AVERAGE('RESULTADO (DRE)'!S23:U23) -> 0.96831011
C37: WACC ano | D37: 0.25
C38: WACC quarter | D38: =(1+D37)^(1/4)-1 -> 0.057371263 | J38: Margem Líquida | M38: =AVERAGE('RESULTADO (DRE)'!S75:U75) -> 0.19505752
C40: VPL = | D40: =NPV(D38,'RESULTADO (DRE)'!F82:Q82) -> 532504.49 | J40: Payback (mês) | M40: =VIABILIDADE!D50 -> 21
B42: TIR (IRR) | J42: Breakeven (mês) | M42: =VIABILIDADE!D49 -> 12
C44: IRR (aa) = | D44: =(1+D45)^4-1 -> 2.0150418
C45: IRR (aq) = | D45: =IRR('RESULTADO (DRE)'!F82:Q82) -> 0.31772059
B47: Retorno
C49: Breakeven = | D49: =(1+COUNTBLANK('RESULTADO (DRE)'!F84:Q84))*3 -> 12
C50: Payback = | D50: =(1+COUNTBLANK('RESULTADO (DRE)'!F85:Q85))*3 -> 21
